Workbook

Sheet Data
A1: Row_ID | B1: Order_ID | C1: Order_Date | D1: Ship_Date | E1: Ship_Mode | F1: Customer_ID | G1: Customer_Name | H1: Segment | I1: Country | J1: City | K1: State | L1: Postal_Code | M1: Region | N1: Product_ID | O1: Category | P1: Sub_Category | Q1: Product_Name | R1: Sales | S1: Quantity | T1: Discount | U1: Profit
A2: 1 | B2: CA-2016-152156 | C2: 42682 | D2: 42685 | E2: Second Class | F2: CG-12520 | G2: Claire Gute | H2: Consumer | I2: United States | J2: Henderson | K2: Kentucky | L2: 42420 | M2: South | N2: FUR-BO-10001798 | O2: Furniture | P2: Bookcases | Q2: Bush Somerset Collection Bookcase | R2: 261.96 | S2: 2 | T2: 0 | U2: 41.9136
A3: 2 | B3: CA-2016-152156 | C3: 42682 | D3: 42685 | E3: Second Class | F3: CG-12520 | G3: Claire Gute | H3: Consumer | I3: United States | J3: Henderson | K3: Kentucky | L3: 42420 | M3: South | N3: FUR-CH-10000454 | O3: Furniture | P3: Chairs | Q3: Hon Deluxe Fabric Upholstered Stacking Chairs, Rounded Back | R3: 731.94 | S3: 3 | T3: 0 | U3: 219.582
A4: 3 | B4: CA-2016-138688 | C4: 42533 | D4: 42537 | E4: Second Class | F4: DV-13045 | G4: Darrin Van Huff | H4: Corporate | I4: United States | J4: Los Angeles | K4: California | L4: 90036 | M4: West | N4: OFF-LA-10000240 | O4: Office Supplies | P4: Labels | Q4: Self-Adhesive Address Labels for Typewriters by Universal | R4: 14.62 | S4: 2 | T4: 0 | U4: 6.8714
A5: 4 | B5: US-2015-108966 | C5: 42288 | D5: 42295 | E5: Standard Class | F5: SO-20335 | G5: Sean O'Donnell | H5: Consumer | I5: United States | J5: Fort Lauderdale | K5: Florida | L5: 33311 | M5: South | N5: FUR-TA-10000577 | O5: Furniture | P5: Tables | Q5: Bretford CR4500 Series Slim Rectangular Table | R5: 957.5775 | S5: 5 | T5: 0.45 | U5: -383.031
A6: 5 | B6: US-2015-108966 | C6: 42288 | D6: 42295 | E6: Standard Class | F6: SO-20335 | G6: Sean O'Donnell | H6: Consumer | I6: United States | J6: Fort Lauderdale | K6: Florida | L6: 33311 | M6: South | N6: OFF-ST-10000760 | O6: Office Supplies | P6: Storage | Q6: Eldon Fold 'N Roll Cart System | R6: 22.368 | S6: 2 | T6: 0.2 | U6: 2.5164
A7: 6 | B7: CA-2014-115812 | C7: 41799 | D7: 41804 | E7: Standard Class | F7: BH-11710 | G7: Brosina Hoffman | H7: Consumer | I7: United States | J7: Los Angeles | K7: California | L7: 90032 | M7: West | N7: FUR-FU-10001487 | O7: Furniture | P7: Furnishings | Q7: Eldon Expressions Wood and Plastic Desk Accessories, Cherry Wood | R7: 48.86 | S7: 7 | T7: 0 | U7: 14.1694
A8: 7 | B8: CA-2014-115812 | C8: 41799 | D8: 41804 | E8: Standard Class | F8: BH-11710 | G8: Brosina Hoffman | H8: Consumer | I8: United States | J8: Los Angeles | K8: California | L8: 90032 | M8: West | N8: OFF-AR-10002833 | O8: Office Supplies | P8: Art | Q8: Newell 322 | R8: 7.28 | S8: 4 | T8: 0 | U8: 1.9656
A9: 8 | B9: CA-2014-115812 | C9: 41799 | D9: 41804 | E9: Standard Class | F9: BH-11710 | G9: Brosina Hoffman | H9: Consumer | I9: United States | J9: Los Angeles | K9: California | L9: 90032 | M9: West | N9: TEC-PH-10002275 | O9: Technology | P9: Phones | Q9: Mitel 5320 IP Phone VoIP phone | R9: 907.152 | S9: 6 | T9: 0.2 | U9: 90.7152
A10: 9 | B10: CA-2014-115812 | C10: 41799 | D10: 41804 | E10: Standard Class | F10: BH-11710 | G10: Brosina Hoffman | H10: Consumer | I10: United States | J10: Los Angeles | K10: California | L10: 90032 | M10: West | N10: OFF-BI-10003910 | O10: Office Supplies | P10: Binders | Q10: DXL Angle-View Binders with Locking Rings by Samsill | R10: 18.504 | S10: 3 | T10: 0.2 | U10: 5.7825
A11: 10 | B11: CA-2014-115812 | C11: 41799 | D11: 41804 | E11: Standard Class | F11: BH-11710 | G11: Brosina Hoffman | H11: Consumer | I11: United States | J11: Los Angeles | K11: California | L11: 90032 | M11: West | N11: OFF-AP-10002892 | O11: Office Supplies | P11: Appliances | Q11: Belkin F5C206VTEL 6 Outlet Surge | R11: 114.9 | S11: 5 | T11: 0 | U11: 34.47
A12: 11 | B12: CA-2014-115812 | C12: 41799 | D12: 41804 | E12: Standard Class | F12: BH-11710 | G12: Brosina Hoffman | H12: Consumer | I12: United States | J12: Los Angeles | K12: California | L12: 90032 | M12: West | N12: FUR-TA-10001539 | O12: Furniture | P12: Tables | Q12: Chromcraft Rectangular Conference Tables | R12: 1706.184 | S12: 9 | T12: 0.2 | U12: 85.3092
A13: 12 | B13: CA-2014-115812 | C13: 41799 | D13: 41804 | E13: Standard Class | F13: BH-11710 | G13: Brosina Hoffman | H13: Consumer | I13: United States | J13: Los Angeles | K13: California | L13: 90032 | M13: West | N13: TEC-PH-10002033 | O13: Technology | P13: Phones | Q13: Konftel 250 Conference†phone†- Charcoal black | R13: 911.424 | S13: 4 | T13: 0.2 | U13: 68.3568
... A9995: 9994 | B9995: CA-2017-119914 | C9995: 42859 | D9995: 42864 | E9995: Second Class | F9995: CC-12220 | G9995: Chris Cortes | H9995: Consumer | I9995: United States | J9995: Westminster | K9995: California | L9995: 92683 | M9995: West | N9995: OFF-AP-10002684 | O9995: Office Supplies | P9995: Appliances | Q9995: Acco 7-Outlet Masterpiece Power Center, Wihtout Fax/Phone Line Protection | R9995: 243.16 | S9995: 2 | T9995: 0 | U9995: 72.948

Sheet content
A1: 1. Sales Performance
A2: 1-1. Total Sales
A3: 1-2. Monthly sales trend
A4: 1-3. Top 10 customers
A5: 1-4. Top 10 products
A6: 1-5. Average order value
A8: 2. Profitability Analysis
A9: 2-1. Category profitability
A10: 2-2. Loss-making products
A11: 2-3. Discount impact on profit
A13: 3. Regional analysis
A14: 3-1. Region sales & profit
... A23: 5-2. Average customer spending

Sheet 1-1
A1: SQL | B1: Excel
A2: Total_Sales | B2: Sales | C2: Check
A3: 2297200.9 | B3: =ROUND(SUM(Data!R:R),2) -> 2297200.9 | C3: =A3-B3 -> 0

Sheet 1-2
A1: SQL | E1: Excel | F1: Sum of Sales
A2: Order_Year | B2: Order_Month | C2: Total_Sales | F2: Years (Order_Date) | G2: Months (Order_Date) | H2: Total | I2: Check
A3: 2014 | B3: 1 | C3: 14236.89 | F3: 2014 | G3: Jan | H3: 14236.895 | I3: =C3-H3 -> -0.005
A4: 2014 | B4: 2 | C4: 4519.89 | G4: Feb | H4: 4519.892 | I4: =C4-H4 -> -0.002
A5: 2014 | B5: 3 | C5: 55691.01 | G5: Mar | H5: 55691.009 | I5: =C5-H5 -> 0.00099999997
A6: 2014 | B6: 4 | C6: 28295.34 | G6: Apr | H6: 28295.345 | I6: =C6-H6 -> -0.005
A7: 2014 | B7: 5 | C7: 23648.29 | G7: May | H7: 23648.287 | I7: =C7-H7 -> 0.003
A8: 2014 | B8: 6 | C8: 34595.13 | G8: Jun | H8: 34595.128 | I8: =C8-H8 -> 0.0024
A9: 2014 | B9: 7 | C9: 33946.39 | G9: Jul | H9: 33946.393 | I9: =C9-H9 -> -0.003
A10: 2014 | B10: 8 | C10: 27909.47 | G10: Aug | H10: 27909.468 | I10: =C10-H10 -> 0.0015
A11: 2014 | B11: 9 | C11: 81777.35 | G11: Sep | H11: 81777.351 | I11: =C11-H11 -> -0.00079999997
A12: 2014 | B12: 10 | C12: 31453.39 | G12: Oct | H12: 31453.393 | I12: =C12-H12 -> -0.003
A13: 2014 | B13: 11 | C13: 78628.72 | G13: Nov | H13: 78628.717 | I13: =C13-H13 -> 0.0033
A14: 2014 | B14: 12 | C14: 69545.62 | G14: Dec | H14: 69545.62 | I14: =C14-H14 -> -0.00049999999
A15: 2015 | B15: 1 | C15: 18174.08 | F15: 2015 | G15: Jan | H15: 18174.076 | I15: =C15-H15 -> 0.0044
A16: 2015 | B16: 2 | C16: 11951.41 | G16: Feb | H16: 11951.411 | I16: =C16-H16 -> -0.001
A17: 2015 | B17: 3 | C17: 38726.25 | G17: Mar | H17: 38726.252 | I17: =C17-H17 -> -0.002
A18: 2015 | B18: 4 | C18: 34195.21 | G18: Apr | H18: 34195.208 | I18: =C18-H18 -> 0.0015
A19: 2015 | B19: 5 | C19: 30131.69 | G19: May | H19: 30131.686 | I19: =C19-H19 -> 0.0035
A20: 2015 | B20: 6 | C20: 24797.29 | G20: Jun | H20: 24797.292 | I20: =C20-H20 -> -0.002
A21: 2015 | B21: 7 | C21: 28765.32 | G21: Jul | H21: 28765.325 | I21: =C21-H21 -> -0.005
A22: 2015 | B22: 8 | C22: 36898.33 | G22: Aug | H22: 36898.332 | I22: =C22-H22 -> -0.0022
A23: 2015 | B23: 9 | C23: 64595.92 | G23: Sep | H23: 64595.918 | I23: =C23-H23 -> 0.002
A24: 2015 | B24: 10 | C24: 31404.92 | G24: Oct | H24: 31404.924 | I24: =C24-H24 -> -0.0035
A25: 2015 | B25: 11 | C25: 75972.56 | G25: Nov | H25: 75972.564 | I25: =C25-H25 -> -0.0035
A26: 2015 | B26: 12 | C26: 74919.52 | G26: Dec | H26: 74919.521 | I26: =C26-H26 -> -0.0012000001
A27: 2016 | B27: 1 | C27: 18542.49 | F27: 2016 | G27: Jan | H27: 18542.491 | I27: =C27-H27 -> -0.00099999999
A28: 2016 | B28: 2 | C28: 22978.82 | G28: Feb | H28: 22978.815 | I28: =C28-H28 -> 0.005
A29: 2016 | B29: 3 | C29: 51715.88 | G29: Mar | H29: 51715.875 | I29: =C29-H29 -> 0.005
A30: 2016 | B30: 4 | C30: 38750.04 | G30: Apr | H30: 38750.039 | I30: =C30-H30 -> 0.001
A31: 2016 | B31: 5 | C31: 56987.73 | G31: May | H31: 56987.728 | I31: =C31-H31 -> 0.002
A32: 2016 | B32: 6 | C32: 40344.53 | G32: Jun | H32: 40344.534 | I32: =C32-H32 -> -0.004
A33: 2016 | B33: 7 | C33: 39261.96 | G33: Jul | H33: 39261.963 | I33: =C33-H33 -> -0.003
A34: 2016 | B34: 8 | C34: 31115.37 | G34: Aug | H34: 31115.374 | I34: =C34-H34 -> -0.0043
A35: 2016 | B35: 9 | C35: 73410.02 | G35: Sep | H35: 73410.025 | I35: =C35-H35 -> -0.0049
A36: 2016 | B36: 10 | C36: 59687.75 | G36: Oct | H36: 59687.745 | I36: =C36-H36 -> 0.005
A37: 2016 | B37: 11 | C37: 79411.97 | G37: Nov | H37: 79411.966 | I37: =C37-H37 -> 0.0042
A38: 2016 | B38: 12 | C38: 96999.04 | G38: Dec | H38: 96999.043 | I38: =C38-H38 -> -0.003
A39: 2017 | B39: 1 | C39: 43971.37 | F39: 2017 | G39: Jan | H39: 43971.374 | I39: =C39-H39 -> -0.004
A40: 2017 | B40: 2 | C40: 20301.13 | G40: Feb | H40: 20301.133 | I40: =C40-H40 -> -0.0034
...

Sheet 1-3
A1: SQL | E1: Excel | I1: Check
A2: Customer_ID | B2: Customer_Name | C2: Total_Sales | E2: Row Labels | F2: Customer_Name | G2: Total_Sales | I2: Row Labels | J2: Customer_Name | K2: Total_Sales
A3: SM-20320 | B3: Sean Miller | C3: 25043.05 | E3: SM-20320 | F3: =VLOOKUP(E3,Data!F:G,2,0) -> Sean Miller | G3: =ROUND(SUMIF(Data!G:G,F3,Data!R:R),2) -> 25043.05 | I3: =IF(A3=E3,0,1) -> 0 | J3: =IF(B3=F3,0,1) -> 0 | K3: =IF(C3=G3,0,1) -> 0
A4: TC-20980 | B4: Tamara Chand | C4: 19052.22 | E4: TC-20980 | F4: =VLOOKUP(E4,Data!F:G,2,0) -> Tamara Chand | G4: =ROUND(SUMIF(Data!G:G,F4,Data!R:R),2) -> 19052.22 | I4: =IF(A4=E4,0,1) -> 0 | J4: =IF(B4=F4,0,1) -> 0 | K4: =IF(C4=G4,0,1) -> 0
A5: RB-19360 | B5: Raymond Buch | C5: 15117.34 | E5: RB-19360 | F5: =VLOOKUP(E5,Data!F:G,2,0) -> Raymond Buch | G5: =ROUND(SUMIF(Data!G:G,F5,Data!R:R),2) -> 15117.34 | I5: =IF(A5=E5,0,1) -> 0 | J5: =IF(B5=F5,0,1) -> 0 | K5: =IF(C5=G5,0,1) -> 0
A6: TA-21385 | B6: Tom Ashbrook | C6: 14595.62 | E6: TA-21385 | F6: =VLOOKUP(E6,Data!F:G,2,0) -> Tom Ashbrook | G6: =ROUND(SUMIF(Data!G:G,F6,Data!R:R),2) -> 14595.62 | I6: =IF(A6=E6,0,1) -> 0 | J6: =IF(B6=F6,0,1) -> 0 | K6: =IF(C6=G6,0,1) -> 0
A7: AB-10105 | B7: Adrian Barton | C7: 14473.57 | E7: AB-10105 | F7: =VLOOKUP(E7,Data!F:G,2,0) -> Adrian Barton | G7: =ROUND(SUMIF(Data!G:G,F7,Data!R:R),2) -> 14473.57 | I7: =IF(A7=E7,0,1) -> 0 | J7: =IF(B7=F7,0,1) -> 0 | K7: =IF(C7=G7,0,1) -> 0
A8: KL-16645 | B8: Ken Lonsdale | C8: 14175.23 | E8: KL-16645 | F8: =VLOOKUP(E8,Data!F:G,2,0) -> Ken Lonsdale | G8: =ROUND(SUMIF(Data!G:G,F8,Data!R:R),2) -> 14175.23 | I8: =IF(A8=E8,0,1) -> 0 | J8: =IF(B8=F8,0,1) -> 0 | K8: =IF(C8=G8,0,1) -> 0
A9: SC-20095 | B9: Sanjit Chand | C9: 14142.33 | E9: SC-20095 | F9: =VLOOKUP(E9,Data!F:G,2,0) -> Sanjit Chand | G9: =ROUND(SUMIF(Data!G:G,F9,Data!R:R),2) -> 14142.33 | I9: =IF(A9=E9,0,1) -> 0 | J9: =IF(B9=F9,0,1) -> 0 | K9: =IF(C9=G9,0,1) -> 0
A10: HL-15040 | B10: Hunter Lopez | C10: 12873.3 | E10: HL-15040 | F10: =VLOOKUP(E10,Data!F:G,2,0) -> Hunter Lopez | G10: =ROUND(SUMIF(Data!G:G,F10,Data!R:R),2) -> 12873.3 | I10: =IF(A10=E10,0,1) -> 0 | J10: =IF(B10=F10,0,1) -> 0 | K10: =IF(C10=G10,0,1) -> 0
A11: SE-20110 | B11: Sanjit Engle | C11: 12209.44 | E11: SE-20110 | F11: =VLOOKUP(E11,Data!F:G,2,0) -> Sanjit Engle | G11: =ROUND(SUMIF(Data!G:G,F11,Data!R:R),2) -> 12209.44 | I11: =IF(A11=E11,0,1) -> 0 | J11: =IF(B11=F11,0,1) -> 0 | K11: =IF(C11=G11,0,1) -> 0
A12: CC-12370 | B12: Christopher Conant | C12: 12129.07 | E12: CC-12370 | F12: =VLOOKUP(E12,Data!F:G,2,0) -> Christopher Conant | G12: =ROUND(SUMIF(Data!G:G,F12,Data!R:R),2) -> 12129.07 | I12: =IF(A12=E12,0,1) -> 0 | J12: =IF(B12=F12,0,1) -> 0 | K12: =IF(C12=G12,0,1) -> 0
E13: TS-21370 | F13: =VLOOKUP(E13,Data!F:G,2,0) -> Todd Sumrall | G13: =ROUND(SUMIF(Data!G:G,F13,Data!R:R),2) -> 11891.75
E14: GT-14710 | F14: =VLOOKUP(E14,Data!F:G,2,0) -> Greg Tran | G14: =ROUND(SUMIF(Data!G:G,F14,Data!R:R),2) -> 11820.12
E15: BM-11140 | F15: =VLOOKUP(E15,Data!F:G,2,0) -> Becky Martin | G15: =ROUND(SUMIF(Data!G:G,F15,Data!R:R),2) -> 11789.63
E16: SV-20365 | F16: =VLOOKUP(E16,Data!F:G,2,0) -> Seth Vernon | G16: =ROUND(SUMIF(Data!G:G,F16,Data!R:R),2) -> 11470.95
E17: CJ-12010 | F17: =VLOOKUP(E17,Data!F:G,2,0) -> Caroline Jumper | G17: =ROUND(SUMIF(Data!G:G,F17,Data!R:R),2) -> 11164.97
E18: CL-12565 | F18: =VLOOKUP(E18,Data!F:G,2,0) -> Clay Ludtke | G18: =ROUND(SUMIF(Data!G:G,F18,Data!R:R),2) -> 10880.55
E19: ME-17320 | F19: =VLOOKUP(E19,Data!F:G,2,0) -> Maria Etezadi | G19: =ROUND(SUMIF(Data!G:G,F19,Data!R:R),2) -> 10663.73
E20: KF-16285 | F20: =VLOOKUP(E20,Data!F:G,2,0) -> Karen Ferguson | G20: =ROUND(SUMIF(Data!G:G,F20,Data!R:R),2) -> 10604.27
E21: BS-11365 | F21: =VLOOKUP(E21,Data!F:G,2,0) -> Bill Shonely | G21: =ROUND(SUMIF(Data!G:G,F21,Data!R:R),2) -> 10501.65
E22: EH-13765 | F22: =VLOOKUP(E22,Data!F:G,2,0) -> Edward Hooks | G22: =ROUND(SUMIF(Data!G:G,F22,Data!R:R),2) -> 10310.88
E23: JL-15835 | F23: =VLOOKUP(E23,Data!F:G,2,0) -> John Lee | G23: =ROUND(SUMIF(Data!G:G,F23,Data!R:R),2) -> 9799.92
E24: GT-14635 | F24: =VLOOKUP(E24,Data!F:G,2,0) -> Grant Thornton | G24: =ROUND(SUMIF(Data!G:G,F24,Data!R:R),2) -> 9351.21
... E797: Grand Total | F797: =VLOOKUP(E797,Data!F:G,2,0) -> #N/A | G797: =ROUND(SUMIF(Data!G:G,F797,Data!R:R),2) -> 0

Sheet 1-4
A1: SQL | G1: Excel | M1: Check
A2: Product_ID | B2: Category | C2: Sub_Category | D2: Product_Name | E2: Total_Sales | G2: Row Labels | H2: Category | I2: Sub_Category | J2: Product_Name | K2: Total_Sales | M2: Row Labels | N2: Category | O2: Sub_Category | P2: Product_Name | Q2: Total_Sales
A3: TEC-CO-10004722 | B3: Technology | C3: Copiers | D3: Canon imageCLASS 2200 Advanced Copier | E3: 61599.82 | G3: TEC-CO-10004722 | H3: =VLOOKUP(G3,Data!$N:$Q,2,0) -> Technology | I3: =VLOOKUP(G3,Data!$N:$Q,3,0) -> Copiers | J3: =VLOOKUP(G3,Data!$N:$Q,4,0) -> Canon imageCLASS 2200 Advanced Copier | K3: =ROUND(SUMIF(Data!N:N,G3,Data!R:R),2) -> 61599.82 | M3: =IF(A3=G3,0,1) -> 0 | N3: =IF(B3=H3,0,1) -> 0 | O3: =IF(C3=I3,0,1) -> 0 | P3: =IF(D3=J3,0,1) -> 0 | Q3: =IF(E3=K3,0,1) -> 0
A4: OFF-BI-10003527 | B4: Office Supplies | C4: Binders | D4: Fellowes PB500 Electric Punch Plastic Comb Binding Machine with Manual Bind | E4: 27453.38 | G4: OFF-BI-10003527 | H4: =VLOOKUP(G4,Data!$N:$Q,2,0) -> Office Supplies | I4: =VLOOKUP(G4,Data!$N:$Q,3,0) -> Binders | J4: =VLOOKUP(G4,Data!$N:$Q,4,0) -> Fellowes PB500 Electric Punch Plastic Comb Binding Machine with Manual Bind | K4: =ROUND(SUMIF(Data!N:N,G4,Data!R:R),2) -> 27453.38 | M4: =IF(A4=G4,0,1) -> 0 | N4: =IF(B4=H4,0,1) -> 0 | O4: =IF(C4=I4,0,1) -> 0 | P4: =IF(D4=J4,0,1) -> 0 | Q4: =IF(E4=K4,0,1) -> 0
A5: TEC-MA-10002412 | B5: Technology | C5: Machines | D5: Cisco TelePresence System EX90 Videoconferencing Unit | E5: 22638.48 | G5: TEC-MA-10002412 | H5: =VLOOKUP(G5,Data!$N:$Q,2,0) -> Technology | I5: =VLOOKUP(G5,Data!$N:$Q,3,0) -> Machines | J5: =VLOOKUP(G5,Data!$N:$Q,4,0) -> Cisco TelePresence System EX90 Videoconferencing Unit | K5: =ROUND(SUMIF(Data!N:N,G5,Data!R:R),2) -> 22638.48 | M5: =IF(A5=G5,0,1) -> 0 | N5: =IF(B5=H5,0,1) -> 0 | O5: =IF(C5=I5,0,1) -> 0 | P5: =IF(D5=J5,0,1) -> 0 | Q5: =IF(E5=K5,0,1) -> 0
A6: FUR-CH-10002024 | B6: Furniture | C6: Chairs | D6: HON 5400 Series Task Chairs for Big and Tall | E6: 21870.58 | G6: FUR-CH-10002024 | H6: =VLOOKUP(G6,Data!$N:$Q,2,0) -> Furniture | I6: =VLOOKUP(G6,Data!$N:$Q,3,0) -> Chairs | J6: =VLOOKUP(G6,Data!$N:$Q,4,0) -> HON 5400 Series Task Chairs for Big and Tall | K6: =ROUND(SUMIF(Data!N:N,G6,Data!R:R),2) -> 21870.58 | M6: =IF(A6=G6,0,1) -> 0 | N6: =IF(B6=H6,0,1) -> 0 | O6: =IF(C6=I6,0,1) -> 0 | P6: =IF(D6=J6,0,1) -> 0 | Q6: =IF(E6=K6,0,1) -> 0
A7: OFF-BI-10001359 | B7: Office Supplies | C7: Binders | D7: GBC DocuBind TL300 Electric Binding System | E7: 19823.48 | G7: OFF-BI-10001359 | H7: =VLOOKUP(G7,Data!$N:$Q,2,0) -> Office Supplies | I7: =VLOOKUP(G7,Data!$N:$Q,3,0) -> Binders | J7: =VLOOKUP(G7,Data!$N:$Q,4,0) -> GBC DocuBind TL300 Electric Binding System | K7: =ROUND(SUMIF(Data!N:N,G7,Data!R:R),2) -> 19823.48 | M7: =IF(A7=G7,0,1) -> 0 | N7: =IF(B7=H7,0,1) -> 0 | O7: =IF(C7=I7,0,1) -> 0 | P7: =IF(D7=J7,0,1) -> 0 | Q7: =IF(E7=K7,0,1) -> 0
A8: OFF-BI-10000545 | B8: Office Supplies | C8: Binders | D8: GBC Ibimaster 500 Manual ProClick Binding System | E8: 19024.5 | G8: OFF-BI-10000545 | H8: =VLOOKUP(G8,Data!$N:$Q,2,0) -> Office Supplies | I8: =VLOOKUP(G8,Data!$N:$Q,3,0) -> Binders | J8: =VLOOKUP(G8,Data!$N:$Q,4,0) -> GBC Ibimaster 500 Manual ProClick Binding System | K8: =ROUND(SUMIF(Data!N:N,G8,Data!R:R),2) -> 19024.5 | M8: =IF(A8=G8,0,1) -> 0 | N8: =IF(B8=H8,0,1) -> 0 | O8: =IF(C8=I8,0,1) -> 0 | P8: =IF(D8=J8,0,1) -> 0 | Q8: =IF(E8=K8,0,1) -> 0
A9: TEC-CO-10001449 | B9: Technology | C9: Copiers | D9: Hewlett Packard LaserJet 3310 Copier | E9: 18839.69 | G9: TEC-CO-10001449 | H9: =VLOOKUP(G9,Data!$N:$Q,2,0) -> Technology | I9: =VLOOKUP(G9,Data!$N:$Q,3,0) -> Copiers | J9: =VLOOKUP(G9,Data!$N:$Q,4,0) -> Hewlett Packard LaserJet 3310 Copier | K9: =ROUND(SUMIF(Data!N:N,G9,Data!R:R),2) -> 18839.69 | M9: =IF(A9=G9,0,1) -> 0 | N9: =IF(B9=H9,0,1) -> 0 | O9: =IF(C9=I9,0,1) -> 0 | P9: =IF(D9=J9,0,1) -> 0 | Q9: =IF(E9=K9,0,1) -> 0
A10: TEC-MA-10001127 | B10: Technology | C10: Machines | D10: HP Designjet T520 Inkjet Large Format Printer - 24" Color | E10: 18374.9 | G10: TEC-MA-10001127 | H10: =VLOOKUP(G10,Data!$N:$Q,2,0) -> Technology | I10: =VLOOKUP(G10,Data!$N:$Q,3,0) -> Machines | J10: =VLOOKUP(G10,Data!$N:$Q,4,0) -> HP Designjet T520 Inkjet Large Format Printer - 24" Color | K10: =ROUND(SUMIF(Data!N:N,G10,Data!R:R),2) -> 18374.9 | M10: =IF(A10=G10,0,1) -> 0 | N10: =IF(B10=H10,0,1) -> 0 | O10: =IF(C10=I10,0,1) -> 0 | P10: =IF(D10=J10,0,1) -> 0 | Q10: =IF(E10=K10,0,1) -> 0
A11: OFF-BI-10004995 | B11: Office Supplies | C11: Binders | D11: GBC DocuBind P400 Electric Binding System | E11: 17965.07 | G11: OFF-BI-10004995 | H11: =VLOOKUP(G11,Data!$N:$Q,2,0) -> Office Supplies | I11: =VLOOKUP(G11,Data!$N:$Q,3,0) -> Binders | J11: =VLOOKUP(G11,Data!$N:$Q,4,0) -> GBC DocuBind P400 Electric Binding System | K11: =ROUND(SUMIF(Data!N:N,G11,Data!R:R),2) -> 17965.07 | M11: =IF(A11=G11,0,1) -> 0 | N11: =IF(B11=H11,0,1) -> 0 | O11: =IF(C11=I11,0,1) -> 0 | P11: =IF(D11=J11,0,1) -> 0 | Q11: =IF(E11=K11,0,1) -> 0
A12: OFF-SU-10000151 | B12: Office Supplies | C12: Supplies | D12: High Speed Automatic Electric Letter Opener | E12: 17030.31 | G12: OFF-SU-10000151 | H12: =VLOOKUP(G12,Data!$N:$Q,2,0) -> Office Supplies | I12: =VLOOKUP(G12,Data!$N:$Q,3,0) -> Supplies | J12: =VLOOKUP(G12,Data!$N:$Q,4,0) -> High Speed Automatic Electric Letter Opener | K12: =ROUND(SUMIF(Data!N:N,G12,Data!R:R),2) -> 17030.31 | M12: =IF(A12=G12,0,1) -> 0 | N12: =IF(B12=H12,0,1) -> 0 | O12: =IF(C12=I12,0,1) -> 0 | P12: =IF(D12=J12,0,1) -> 0 | Q12: =IF(E12=K12,0,1) -> 0
G13: TEC-MA-10000822 | H13: =VLOOKUP(G13,Data!$N:$Q,2,0) -> Technology | I13: =VLOOKUP(G13,Data!$N:$Q,3,0) -> Machines | J13: =VLOOKUP(G13,Data!$N:$Q,4,0) -> Lexmark MX611dhe Monochrome Laser Printer | K13: =ROUND(SUMIF(Data!N:N,G13,Data!R:R),2) -> 16829.9
G14: OFF-SU-10002881 | H14: =VLOOKUP(G14,Data!$N:$Q,2,0) -> Office Supplies | I14: =VLOOKUP(G14,Data!$N:$Q,3,0) -> Supplies | J14: =VLOOKUP(G14,Data!$N:$Q,4,0) -> Martin Yale Chadless Opener Electric Letter Opener | K14: =ROUND(SUMIF(Data!N:N,G14,Data!R:R),2) -> 16656.2
G15: OFF-BI-10001120 | H15: =VLOOKUP(G15,Data!$N:$Q,2,0) -> Office Supplies | I15: =VLOOKUP(G15,Data!$N:$Q,3,0) -> Binders | J15: =VLOOKUP(G15,Data!$N:$Q,4,0) -> Ibico EPK-21 Electric Binding System | K15: =ROUND(SUMIF(Data!N:N,G15,Data!R:R),2) -> 15875.92
G16: FUR-BO-10004834 | H16: =VLOOKUP(G16,Data!$N:$Q,2,0) -> Furniture | I16: =VLOOKUP(G16,Data!$N:$Q,3,0) -> Bookcases | J16: =VLOOKUP(G16,Data!$N:$Q,4,0) -> Riverside Palais Royal Lawyers Bookcase, Royale Cherry Finish | K16: =ROUND(SUMIF(Data!N:N,G16,Data!R:R),2) -> 15610.97
G17: TEC-MA-10001047 | H17: =VLOOKUP(G17,Data!$N:$Q,2,0) -> Technology | I17: =VLOOKUP(G17,Data!$N:$Q,3,0) -> Machines | J17: =VLOOKUP(G17,Data!$N:$Q,4,0) -> 3D Systems Cube Printer, 2nd Generation, Magenta | K17: =ROUND(SUMIF(Data!N:N,G17,Data!R:R),2) -> 14299.89
G18: TEC-PH-10001459 | H18: =VLOOKUP(G18,Data!$N:$Q,2,0) -> Technology | I18: =VLOOKUP(G18,Data!$N:$Q,3,0) -> Phones | J18: =VLOOKUP(G18,Data!$N:$Q,4,0) -> Samsung Galaxy Mega 6.3 | K18: =ROUND(SUMIF(Data!N:N,G18,Data!R:R),2) -> 13943.67
G19: TEC-AC-10002049 | H19: =VLOOKUP(G19,Data!$N:$Q,2,0) -> Technology | I19: =VLOOKUP(G19,Data!$N:$Q,3,0) -> Accessories | J19: =VLOOKUP(G19,Data!$N:$Q,4,0) -> Logitech G19 Programmable Gaming Keyboard | K19: =ROUND(SUMIF(Data!N:N,G19,Data!R:R),2) -> 13756.54
G20: TEC-PH-10002885 | H20: =VLOOKUP(G20,Data!$N:$Q,2,0) -> Technology | I20: =VLOOKUP(G20,Data!$N:$Q,3,0) -> Phones | J20: =VLOOKUP(G20,Data!$N:$Q,4,0) -> Apple iPhone 5 | K20: =ROUND(SUMIF(Data!N:N,G20,Data!R:R),2) -> 12996.6
G21: FUR-TA-10003473 | H21: =VLOOKUP(G21,Data!$N:$Q,2,0) -> Furniture | I21: =VLOOKUP(G21,Data!$N:$Q,3,0) -> Tables | J21: =VLOOKUP(G21,Data!$N:$Q,4,0) -> Bretford Rectangular Conference Table Tops | K21: =ROUND(SUMIF(Data!N:N,G21,Data!R:R),2) -> 12995.29
G22: FUR-CH-10001215 | H22: =VLOOKUP(G22,Data!$N:$Q,2,0) -> Furniture | I22: =VLOOKUP(G22,Data!$N:$Q,3,0) -> Chairs | J22: =VLOOKUP(G22,Data!$N:$Q,4,0) -> Global Troy Executive Leather Low-Back Tilter | K22: =ROUND(SUMIF(Data!N:N,G22,Data!R:R),2) -> 12975.38
G23: FUR-BO-10002213 | H23: =VLOOKUP(G23,Data!$N:$Q,2,0) -> Furniture | I23: =VLOOKUP(G23,Data!$N:$Q,3,0) -> Bookcases | J23: =VLOOKUP(G23,Data!$N:$Q,4,0) -> DMI Eclipse Executive Suite Bookcases | K23: =ROUND(SUMIF(Data!N:N,G23,Data!R:R),2) -> 12921.64
G24: TEC-CO-10003763 | H24: =VLOOKUP(G24,Data!$N:$Q,2,0) -> Technology | I24: =VLOOKUP(G24,Data!$N:$Q,3,0) -> Copiers | J24: =VLOOKUP(G24,Data!$N:$Q,4,0) -> Canon PC1060 Personal Laser Copier | K24: =ROUND(SUMIF(Data!N:N,G24,Data!R:R),2) -> 11619.83
... G1865: Grand Total | H1865: =VLOOKUP(G1865,Data!$N:$Q,2,0) -> #N/A | I1865: =VLOOKUP(G1865,Data!$N:$Q,3,0) -> #N/A | J1865: =VLOOKUP(G1865,Data!$N:$Q,4,0) -> #N/A | K1865: =ROUND(SUMIF(Data!N:N,G1865,Data!R:R),2) -> 0

Sheet 1-5
A1: SQL
A2: Total_Orders | B2: Total_Sales | C2: Average_Order_Value
A3: 5009 | B3: 2297200.9 | C3: 458.61
A6: Excel
A7: Total_Orders | B7: Total_Sales | C7: Average_Order_Value
A8: =COUNTA(_xlfn.UNIQUE(Data!B2:B9995)) -> 5009 | B8: =ROUND(SUM(Data!R:R),2) -> 2297200.9 | C8: =ROUND(B8/A8,2) -> 458.61
A10: Check
A11: Total_Orders | B11: Total_Sales | C11: Average_Order_Value
A12: =A3-A8 -> 0 | B12: =B3-B8 -> 0 | C12: =C3-C8 -> 0

Sheet 2-1
A1: SQL | D1: Excel
A2: Category | B2: Total_Profit | D2: Category | E2: Profit | G2: Check
A3: Technology | B3: 145454.95 | D3: Technology | E3: =ROUND(SUMIF(Data!O:O,'2-1'!D3,Data!U:U),2) -> 145454.95 | G3: =B3-E3 -> 0
A4: Office Supplies | B4: 122490.8 | D4: Office Supplies | E4: =ROUND(SUMIF(Data!O:O,'2-1'!D4,Data!U:U),2) -> 122490.8 | G4: =B4-E4 -> 0
A5: Furniture | B5: 18451.27 | D5: Furniture | E5: =ROUND(SUMIF(Data!O:O,'2-1'!D5,Data!U:U),2) -> 18451.27 | G5: =B5-E5 -> 0

Sheet 2-2
A1: SQL | D1: Excel
A2: Product_Name | B2: Total_Profit | D2: Product_Name | E2: Profit | G2: Check
A3: Cubify CubeX 3D Printer Double Head Print | B3: -9239.97 | D3: Cubify CubeX 3D Printer Double Head Print | E3: =ROUND(SUMIFS(Data!U:U,Data!U:U,"<0",Data!Q:Q,'2-2'!D3),2) -> -9239.97 | G3: =B3-E3 -> 0
A4: GBC DocuBind P400 Electric Binding System | B4: -6859.39 | D4: GBC DocuBind P400 Electric Binding System | E4: =ROUND(SUMIFS(Data!U:U,Data!U:U,"<0",Data!Q:Q,'2-2'!D4),2) -> -6859.39 | G4: =B4-E4 -> 0
A5: Lexmark MX611dhe Monochrome Laser Printer | B5: -5269.97 | D5: Lexmark MX611dhe Monochrome Laser Printer | E5: =ROUND(SUMIFS(Data!U:U,Data!U:U,"<0",Data!Q:Q,'2-2'!D5),2) -> -5269.97 | G5: =B5-E5 -> 0
A6: GBC Ibimaster 500 Manual ProClick Binding System | B6: -5098.57 | D6: GBC Ibimaster 500 Manual ProClick Binding System | E6: =ROUND(SUMIFS(Data!U:U,Data!U:U,"<0",Data!Q:Q,'2-2'!D6),2) -> -5098.57 | G6: =B6-E6 -> 0
A7: GBC DocuBind TL300 Electric Binding System | B7: -4162.03 | D7: GBC DocuBind TL300 Electric Binding System | E7: =ROUND(SUMIFS(Data!U:U,Data!U:U,"<0",Data!Q:Q,'2-2'!D7),2) -> -4162.03 | G7: =B7-E7 -> 0
A8: Cubify CubeX 3D Printer Triple Head Print | B8: -3839.99 | D8: Cubify CubeX 3D Printer Triple Head Print | E8: =ROUND(SUMIFS(Data!U:U,Data!U:U,"<0",Data!Q:Q,'2-2'!D8),2) -> -3839.99 | G8: =B8-E8 -> 0
A9: Fellowes PB500 Electric Punch Plastic Comb Binding Machine with Manual Bind | B9: -3431.67 | D9: Fellowes PB500 Electric Punch Plastic Comb Binding Machine with Manual Bind | E9: =ROUND(SUMIFS(Data!U:U,Data!U:U,"<0",Data!Q:Q,'2-2'!D9),2) -> -3431.67 | G9: =B9-E9 -> 0
A10: Chromcraft Bull-Nose Wood Oval Conference Tables & Bases | B10: -3107.53 | D10: Chromcraft Bull-Nose Wood Oval Conference Tables & Bases | E10: =ROUND(SUMIFS(Data!U:U,Data!U:U,"<0",Data!Q:Q,'2-2'!D10),2) -> -3107.53 | G10: =B10-E10 -> 0
A11: Ibico EPK-21 Electric Binding System | B11: -2929.48 | D11: Ibico EPK-21 Electric Binding System | E11: =ROUND(SUMIFS(Data!U:U,Data!U:U,"<0",Data!Q:Q,'2-2'!D11),2) -> -2929.48 | G11: =B11-E11 -> 0
A12: Bush Advantage Collection Racetrack Conference Table | B12: -2545.26 | D12: Bush Advantage Collection Racetrack Conference Table | E12: =ROUND(SUMIFS(Data!U:U,Data!U:U,"<0",Data!Q:Q,'2-2'!D12),2) -> -2545.26 | G12: =B12-E12 -> 0
A13: Riverside Palais Royal Lawyers Bookcase, Royale Cherry Finish | B13: -1982.21 | D13: Riverside Palais Royal Lawyers Bookcase, Royale Cherry Finish | E13: =ROUND(SUMIFS(Data!U:U,Data!U:U,"<0",Data!Q:Q,'2-2'!D13),2) -> -1982.21 | G13: =B13-E13 -> 0
A14: Ibico Hi-Tech Manual Binding System | B14: -1829.94 | D14: Ibico Hi-Tech Manual Binding System | E14: =ROUND(SUMIFS(Data!U:U,Data!U:U,"<0",Data!Q:Q,'2-2'!D14),2) -> -1829.94 | G14: =B14-E14 -> 0
... A52: Tenex Chairmat w/ Average Lip, 45" x 53" | B52: -681.12 | D52: Tenex Chairmat w/ Average Lip, 45" x 53" | E52: =ROUND(SUMIFS(Data!U:U,Data!U:U,"<0",Data!Q:Q,'2-2'!D52),2) -> -681.12 | G52: =B52-E52 -> 0

Sheet 2-3
A1: SQL | H1: Excel
A2: Discount | B2: Total_Sales | C2: Total_Profit | D2: Average_Profit | E2: Profit_Margin_Percentage | F2: Number_of_Orders | H2: Discount | I2: Total_Sales | J2: Total_Profit | K2: Average_Profit | L2: Profit_Margin_Percentage | M2: Number_of_Orders | O2: Check
A3: 0.8 | B3: 16963.76 | C3: -30539.04 | D3: -101.8 | E3: -180.03 | F3: 300 | H3: 0.8 | I3: =ROUND(SUMIF(Data!T:T,H3,Data!R:R),2) -> 16963.76 | J3: =ROUND(SUMIF(Data!T:T,H3,Data!U:U),2) -> -30539.04 | K3: =ROUND(J3/M3,2) -> -101.8 | L3: =ROUND(J3/I3*100,2) -> -180.03 | M3: =COUNTIF(Data!T:T,H3) -> 300 | O3: =H3-A3 -> 0 | P3: =I3-B3 -> 0 | Q3: =J3-C3 -> 0 | R3: =K3-D3 -> 0 | S3: =L3-E3 -> 0 | T3: =M3-F3 -> 0
A4: 0.7 | B4: 40620.28 | C4: -40075.36 | D4: -95.87 | E4: -98.66 | F4: 418 | H4: 0.7 | I4: =ROUND(SUMIF(Data!T:T,H4,Data!R:R),2) -> 40620.28 | J4: =ROUND(SUMIF(Data!T:T,H4,Data!U:U),2) -> -40075.36 | K4: =ROUND(J4/M4,2) -> -95.87 | L4: =ROUND(J4/I4*100,2) -> -98.66 | M4: =COUNTIF(Data!T:T,H4) -> 418 | O4: =H4-A4 -> 0 | P4: =I4-B4 -> 0 | Q4: =J4-C4 -> 0 | R4: =K4-D4 -> 0 | S4: =L4-E4 -> 0 | T4: =M4-F4 -> 0
A5: 0.6 | B5: 6644.7 | C5: -5944.66 | D5: -43.08 | E5: -89.46 | F5: 138 | H5: 0.6 | I5: =ROUND(SUMIF(Data!T:T,H5,Data!R:R),2) -> 6644.7 | J5: =ROUND(SUMIF(Data!T:T,H5,Data!U:U),2) -> -5944.66 | K5: =ROUND(J5/M5,2) -> -43.08 | L5: =ROUND(J5/I5*100,2) -> -89.46 | M5: =COUNTIF(Data!T:T,H5) -> 138 | O5: =H5-A5 -> 0 | P5: =I5-B5 -> 0 | Q5: =J5-C5 -> 0 | R5: =K5-D5 -> 0 | S5: =L5-E5 -> 0 | T5: =M5-F5 -> 0
A6: 0.45 | B6: 5484.97 | C6: -2493.11 | D6: -226.65 | E6: -45.45 | F6: 11 | H6: 0.45 | I6: =ROUND(SUMIF(Data!T:T,H6,Data!R:R),2) -> 5484.97 | J6: =ROUND(SUMIF(Data!T:T,H6,Data!U:U),2) -> -2493.11 | K6: =ROUND(J6/M6,2) -> -226.65 | L6: =ROUND(J6/I6*100,2) -> -45.45 | M6: =COUNTIF(Data!T:T,H6) -> 11 | O6: =H6-A6 -> 0 | P6: =I6-B6 -> 0 | Q6: =J6-C6 -> 0 | R6: =K6-D6 -> 0 | S6: =L6-E6 -> 0 | T6: =M6-F6 -> 0
A7: 0.5 | B7: 58918.54 | C7: -20506.43 | D7: -310.7 | E7: -34.8 | F7: 66 | H7: 0.5 | I7: =ROUND(SUMIF(Data!T:T,H7,Data!R:R),2) -> 58918.54 | J7: =ROUND(SUMIF(Data!T:T,H7,Data!U:U),2) -> -20506.43 | K7: =ROUND(J7/M7,2) -> -310.7 | L7: =ROUND(J7/I7*100,2) -> -34.8 | M7: =COUNTIF(Data!T:T,H7) -> 66 | O7: =H7-A7 -> 0 | P7: =I7-B7 -> 0 | Q7: =J7-C7 -> 0 | R7: =K7-D7 -> 0 | S7: =L7-E7 -> 0 | T7: =M7-F7 -> 0
A8: 0.4 | B8: 116417.78 | C8: -23057.05 | D8: -111.93 | E8: -19.81 | F8: 206 | H8: 0.4 | I8: =ROUND(SUMIF(Data!T:T,H8,Data!R:R),2) -> 116417.78 | J8: =ROUND(SUMIF(Data!T:T,H8,Data!U:U),2) -> -23057.05 | K8: =ROUND(J8/M8,2) -> -111.93 | L8: =ROUND(J8/I8*100,2) -> -19.81 | M8: =COUNTIF(Data!T:T,H8) -> 206 | O8: =H8-A8 -> 0 | P8: =I8-B8 -> 0 | Q8: =J8-C8 -> 0 | R8: =K8-D8 -> 0 | S8: =L8-E8 -> 0 | T8: =M8-F8 -> 0
A9: 0.32 | B9: 14493.46 | C9: -2391.14 | D9: -88.56 | E9: -16.5 | F9: 27 | H9: 0.32 | I9: =ROUND(SUMIF(Data!T:T,H9,Data!R:R),2) -> 14493.46 | J9: =ROUND(SUMIF(Data!T:T,H9,Data!U:U),2) -> -2391.14 | K9: =ROUND(J9/M9,2) -> -88.56 | L9: =ROUND(J9/I9*100,2) -> -16.5 | M9: =COUNTIF(Data!T:T,H9) -> 27 | O9: =H9-A9 -> 0 | P9: =I9-B9 -> 0 | Q9: =J9-C9 -> 0 | R9: =K9-D9 -> 0 | S9: =L9-E9 -> 0 | T9: =M9-F9 -> 0
A10: 0.3 | B10: 103226.65 | C10: -10369.28 | D10: -45.68 | E10: -10.05 | F10: 227 | H10: 0.3 | I10: =ROUND(SUMIF(Data!T:T,H10,Data!R:R),2) -> 103226.66 | J10: =ROUND(SUMIF(Data!T:T,H10,Data!U:U),2) -> -10369.28 | K10: =ROUND(J10/M10,2) -> -45.68 | L10: =ROUND(J10/I10*100,2) -> -10.05 | M10: =COUNTIF(Data!T:T,H10) -> 227 | O10: =H10-A10 -> 0 | P10: =I10-B10 -> 0.01 | Q10: =J10-C10 -> 0 | R10: =K10-D10 -> 0 | S10: =L10-E10 -> 0 | T10: =M10-F10 -> 0
A11: 0.15 | B11: 27558.52 | C11: 1418.99 | D11: 27.29 | E11: 5.15 | F11: 52 | H11: 0.15 | I11: =ROUND(SUMIF(Data!T:T,H11,Data!R:R),2) -> 27558.52 | J11: =ROUND(SUMIF(Data!T:T,H11,Data!U:U),2) -> 1418.99 | K11: =ROUND(J11/M11,2) -> 27.29 | L11: =ROUND(J11/I11*100,2) -> 5.15 | M11: =COUNTIF(Data!T:T,H11) -> 52 | O11: =H11-A11 -> 0 | P11: =I11-B11 -> 0 | Q11: =J11-C11 -> 0 | R11: =K11-D11 -> 0 | S11: =L11-E11 -> 0 | T11: =M11-F11 -> 0
A12: 0.2 | B12: 764594.37 | C12: 90337.31 | D12: 24.7 | E12: 11.82 | F12: 3657 | H12: 0.2 | I12: =ROUND(SUMIF(Data!T:T,H12,Data!R:R),2) -> 764594.37 | J12: =ROUND(SUMIF(Data!T:T,H12,Data!U:U),2) -> 90337.31 | K12: =ROUND(J12/M12,2) -> 24.7 | L12: =ROUND(J12/I12*100,2) -> 11.82 | M12: =COUNTIF(Data!T:T,H12) -> 3657 | O12: =H12-A12 -> 0 | P12: =I12-B12 -> 0 | Q12: =J12-C12 -> 0 | R12: =K12-D12 -> 0 | S12: =L12-E12 -> 0 | T12: =M12-F12 -> 0
A13: 0.1 | B13: 54369.35 | C13: 9029.18 | D13: 96.06 | E13: 16.61 | F13: 94 | H13: 0.1 | I13: =ROUND(SUMIF(Data!T:T,H13,Data!R:R),2) -> 54369.35 | J13: =ROUND(SUMIF(Data!T:T,H13,Data!U:U),2) -> 9029.18 | K13: =ROUND(J13/M13,2) -> 96.06 | L13: =ROUND(J13/I13*100,2) -> 16.61 | M13: =COUNTIF(Data!T:T,H13) -> 94 | O13: =H13-A13 -> 0 | P13: =I13-B13 -> 0 | Q13: =J13-C13 -> 0 | R13: =K13-D13 -> 0 | S13: =L13-E13 -> 0 | T13: =M13-F13 -> 0
A14: 0 | B14: 1087908.5 | C14: 320987.6 | D14: 66.9 | E14: 29.51 | F14: 4798 | H14: 0 | I14: =ROUND(SUMIF(Data!T:T,H14,Data!R:R),2) -> 1087908.5 | J14: =ROUND(SUMIF(Data!T:T,H14,Data!U:U),2) -> 320987.6 | K14: =ROUND(J14/M14,2) -> 66.9 | L14: =ROUND(J14/I14*100,2) -> 29.51 | M14: =COUNTIF(Data!T:T,H14) -> 4798 | O14: =H14-A14 -> 0 | P14: =I14-B14 -> 0 | Q14: =J14-C14 -> 0 | R14: =K14-D14 -> 0 | S14: =L14-E14 -> 0 | T14: =M14-F14 -> 0

Sheet 3-1
A1: SQL | F1: Excel
A2: Region | B2: Total_Sales | C2: Total_Profit | D2: Profit_Margin_Percentage | F2: Region | G2: Total_Sales | H2: Total_Profit | I2: Profit_Margin_Percentage | L2: Check
A3: West | B3: 725457.82 | C3: 108418.45 | D3: 14.94 | F3: =A3 -> West | G3: =ROUND(SUMIF(Data!M:M,F3,Data!R:R),2) -> 725457.82 | H3: =ROUND(SUMIF(Data!M:M,F3,Data!U:U),2) -> 108418.45 | I3: =ROUND(H3/G3*100,2) -> 14.94 | L3: =G3-B3 -> 0 | M3: =H3-C3 -> 0 | N3: =I3-D3 -> 0
A4: East | B4: 678781.24 | C4: 91522.78 | D4: 13.48 | F4: =A4 -> East | G4: =ROUND(SUMIF(Data!M:M,F4,Data!R:R),2) -> 678781.24 | H4: =ROUND(SUMIF(Data!M:M,F4,Data!U:U),2) -> 91522.78 | I4: =ROUND(H4/G4*100,2) -> 13.48 | L4: =G4-B4 -> 0 | M4: =H4-C4 -> 0 | N4: =I4-D4 -> 0
A5: South | B5: 391721.91 | C5: 46749.43 | D5: 11.93 | F5: =A5 -> South | G5: =ROUND(SUMIF(Data!M:M,F5,Data!R:R),2) -> 391721.91 | H5: =ROUND(SUMIF(Data!M:M,F5,Data!U:U),2) -> 46749.43 | I5: =ROUND(H5/G5*100,2) -> 11.93 | L5: =G5-B5 -> 0 | M5: =H5-C5 -> 0 | N5: =I5-D5 -> 0
A6: Central | B6: 501239.89 | C6: 39706.36 | D6: 7.92 | F6: =A6 -> Central | G6: =ROUND(SUMIF(Data!M:M,F6,Data!R:R),2) -> 501239.89 | H6: =ROUND(SUMIF(Data!M:M,F6,Data!U:U),2) -> 39706.36 | I6: =ROUND(H6/G6*100,2) -> 7.92 | L6: =G6-B6 -> 0 | M6: =H6-C6 -> 0 | N6: =I6-D6 -> 0

Sheet 3-2
A1: SQL | D1: Excel
A2: State | B2: Total_Sales | D2: State | E2: Total_Sales | G2: Check
A3: California | B3: 457687.63 | D3: =A3 -> California | E3: =ROUND(SUMIF(Data!K:K,D3,Data!R:R),2) -> 457687.63 | G3: =E3-B3 -> 0
A4: New York | B4: 310876.27 | D4: =A4 -> New York | E4: =ROUND(SUMIF(Data!K:K,D4,Data!R:R),2) -> 310876.27 | G4: =E4-B4 -> 0
A5: Texas | B5: 170188.05 | D5: =A5 -> Texas | E5: =ROUND(SUMIF(Data!K:K,D5,Data!R:R),2) -> 170188.05 | G5: =E5-B5 -> 0
A6: Washington | B6: 138641.27 | D6: =A6 -> Washington | E6: =ROUND(SUMIF(Data!K:K,D6,Data!R:R),2) -> 138641.27 | G6: =E6-B6 -> 0
A7: Pennsylvania | B7: 116511.91 | D7: =A7 -> Pennsylvania | E7: =ROUND(SUMIF(Data!K:K,D7,Data!R:R),2) -> 116511.91 | G7: =E7-B7 -> 0
A8: Florida | B8: 89473.71 | D8: =A8 -> Florida | E8: =ROUND(SUMIF(Data!K:K,D8,Data!R:R),2) -> 89473.71 | G8: =E8-B8 -> 0
A9: Illinois | B9: 80166.1 | D9: =A9 -> Illinois | E9: =ROUND(SUMIF(Data!K:K,D9,Data!R:R),2) -> 80166.1 | G9: =E9-B9 -> 0
A10: Ohio | B10: 78258.14 | D10: =A10 -> Ohio | E10: =ROUND(SUMIF(Data!K:K,D10,Data!R:R),2) -> 78258.14 | G10: =E10-B10 -> 0
A11: Michigan | B11: 76269.61 | D11: =A11 -> Michigan | E11: =ROUND(SUMIF(Data!K:K,D11,Data!R:R),2) -> 76269.61 | G11: =E11-B11 -> 0
A12: Virginia | B12: 70636.72 | D12: =A12 -> Virginia | E12: =ROUND(SUMIF(Data!K:K,D12,Data!R:R),2) -> 70636.72 | G12: =E12-B12 -> 0
A13: North Carolina | B13: 55603.16 | D13: =A13 -> North Carolina | E13: =ROUND(SUMIF(Data!K:K,D13,Data!R:R),2) -> 55603.16 | G13: =E13-B13 -> 0
A14: Indiana | B14: 53555.36 | D14: =A14 -> Indiana | E14: =ROUND(SUMIF(Data!K:K,D14,Data!R:R),2) -> 53555.36 | G14: =E14-B14 -> 0
... A51: North Dakota | B51: 919.91 | D51: =A51 -> North Dakota | E51: =ROUND(SUMIF(Data!K:K,D51,Data!R:R),2) -> 919.91 | G51: =E51-B51 -> 0

Sheet 4-1
A1: SQL | F1: Excel
A2: Sub_Category | B2: total_sales | C2: total_profit | D2: total_quantity | F2: Sub_Category | G2: total_sales | H2: total_profit | I2: total_quantity | K2: Check
A3: Phones | B3: 330007.05 | C3: 44515.73 | D3: 3289 | F3: =A3 -> Phones | G3: =ROUND(SUMIF(Data!P:P,F3,Data!R:R),2) -> 330007.05 | H3: =ROUND(SUMIF(Data!P:P,F3,Data!U:U),2) -> 44515.73 | I3: =SUMIF(Data!P:P,F3,Data!S:S) -> 3289 | K3: =B3-G3 -> 0 | L3: =C3-H3 -> 0 | M3: =D3-I3 -> 0
A4: Chairs | B4: 328449.1 | C4: 26590.17 | D4: 2356 | F4: =A4 -> Chairs | G4: =ROUND(SUMIF(Data!P:P,F4,Data!R:R),2) -> 328449.1 | H4: =ROUND(SUMIF(Data!P:P,F4,Data!U:U),2) -> 26590.17 | I4: =SUMIF(Data!P:P,F4,Data!S:S) -> 2356 | K4: =B4-G4 -> 0 | L4: =C4-H4 -> 0 | M4: =D4-I4 -> 0
A5: Storage | B5: 223843.61 | C5: 21278.83 | D5: 3158 | F5: =A5 -> Storage | G5: =ROUND(SUMIF(Data!P:P,F5,Data!R:R),2) -> 223843.61 | H5: =ROUND(SUMIF(Data!P:P,F5,Data!U:U),2) -> 21278.83 | I5: =SUMIF(Data!P:P,F5,Data!S:S) -> 3158 | K5: =B5-G5 -> 0 | L5: =C5-H5 -> 0 | M5: =D5-I5 -> 0
A6: Tables | B6: 206965.53 | C6: -17725.48 | D6: 1241 | F6: =A6 -> Tables | G6: =ROUND(SUMIF(Data!P:P,F6,Data!R:R),2) -> 206965.53 | H6: =ROUND(SUMIF(Data!P:P,F6,Data!U:U),2) -> -17725.48 | I6: =SUMIF(Data!P:P,F6,Data!S:S) -> 1241 | K6: =B6-G6 -> 0 | L6: =C6-H6 -> 0 | M6: =D6-I6 -> 0
A7: Binders | B7: 203412.73 | C7: 30221.76 | D7: 5974 | F7: =A7 -> Binders | G7: =ROUND(SUMIF(Data!P:P,F7,Data!R:R),2) -> 203412.73 | H7: =ROUND(SUMIF(Data!P:P,F7,Data!U:U),2) -> 30221.76 | I7: =SUMIF(Data!P:P,F7,Data!S:S) -> 5974 | K7: =B7-G7 -> 0 | L7: =C7-H7 -> 0 | M7: =D7-I7 -> 0
A8: Machines | B8: 189238.63 | C8: 3384.76 | D8: 440 | F8: =A8 -> Machines | G8: =ROUND(SUMIF(Data!P:P,F8,Data!R:R),2) -> 189238.63 | H8: =ROUND(SUMIF(Data!P:P,F8,Data!U:U),2) -> 3384.76 | I8: =SUMIF(Data!P:P,F8,Data!S:S) -> 440 | K8: =B8-G8 -> 0 | L8: =C8-H8 -> 0 | M8: =D8-I8 -> 0
A9: Accessories | B9: 167380.32 | C9: 41936.64 | D9: 2976 | F9: =A9 -> Accessories | G9: =ROUND(SUMIF(Data!P:P,F9,Data!R:R),2) -> 167380.32 | H9: =ROUND(SUMIF(Data!P:P,F9,Data!U:U),2) -> 41936.64 | I9: =SUMIF(Data!P:P,F9,Data!S:S) -> 2976 | K9: =B9-G9 -> 0 | L9: =C9-H9 -> 0 | M9: =D9-I9 -> 0
A10: Copiers | B10: 149528.03 | C10: 55617.82 | D10: 234 | F10: =A10 -> Copiers | G10: =ROUND(SUMIF(Data!P:P,F10,Data!R:R),2) -> 149528.03 | H10: =ROUND(SUMIF(Data!P:P,F10,Data!U:U),2) -> 55617.82 | I10: =SUMIF(Data!P:P,F10,Data!S:S) -> 234 | K10: =B10-G10 -> 0 | L10: =C10-H10 -> 0 | M10: =D10-I10 -> 0
A11: Bookcases | B11: 114880 | C11: -3472.56 | D11: 868 | F11: =A11 -> Bookcases | G11: =ROUND(SUMIF(Data!P:P,F11,Data!R:R),2) -> 114880 | H11: =ROUND(SUMIF(Data!P:P,F11,Data!U:U),2) -> -3472.56 | I11: =SUMIF(Data!P:P,F11,Data!S:S) -> 868 | K11: =B11-G11 -> 0 | L11: =C11-H11 -> 0 | M11: =D11-I11 -> 0
A12: Appliances | B12: 107532.16 | C12: 18138.01 | D12: 1729 | F12: =A12 -> Appliances | G12: =ROUND(SUMIF(Data!P:P,F12,Data!R:R),2) -> 107532.16 | H12: =ROUND(SUMIF(Data!P:P,F12,Data!U:U),2) -> 18138.01 | I12: =SUMIF(Data!P:P,F12,Data!S:S) -> 1729 | K12: =B12-G12 -> 0 | L12: =C12-H12 -> 0 | M12: =D12-I12 -> 0
A13: Furnishings | B13: 91705.16 | C13: 13059.14 | D13: 3563 | F13: =A13 -> Furnishings | G13: =ROUND(SUMIF(Data!P:P,F13,Data!R:R),2) -> 91705.16 | H13: =ROUND(SUMIF(Data!P:P,F13,Data!U:U),2) -> 13059.14 | I13: =SUMIF(Data!P:P,F13,Data!S:S) -> 3563 | K13: =B13-G13 -> 0 | L13: =C13-H13 -> 0 | M13: =D13-I13 -> 0
A14: Paper | B14: 78479.21 | C14: 34053.57 | D14: 5178 | F14: =A14 -> Paper | G14: =ROUND(SUMIF(Data!P:P,F14,Data!R:R),2) -> 78479.21 | H14: =ROUND(SUMIF(Data!P:P,F14,Data!U:U),2) -> 34053.57 | I14: =SUMIF(Data!P:P,F14,Data!S:S) -> 5178 | K14: =B14-G14 -> 0 | L14: =C14-H14 -> 0 | M14: =D14-I14 -> 0
... A19: Fasteners | B19: 3024.28 | C19: 949.52 | D19: 914 | F19: =A19 -> Fasteners | G19: =ROUND(SUMIF(Data!P:P,F19,Data!R:R),2) -> 3024.28 | H19: =ROUND(SUMIF(Data!P:P,F19,Data!U:U),2) -> 949.52 | I19: =SUMIF(Data!P:P,F19,Data!S:S) -> 914 | K19: =B19-G19 -> 0 | L19: =C19-H19 -> 0 | M19: =D19-I19 -> 0

Sheet 4-2
A1: SQL | F1: Excel
A2: Product_Name | B2: total_sales | C2: total_profit | D2: total_quantity | F2: Product_Name | G2: total_sales | H2: total_profit | I2: total_quantity | K2: Check
A3: Canon imageCLASS 2200 Advanced Copier | B3: 61599.82 | C3: 25199.93 | D3: 20 | F3: Canon imageCLASS 2200 Advanced Copier | G3: =ROUND(SUMIF(Data!Q:Q,F3,Data!R:R),2) -> 61599.82 | H3: =ROUND(SUMIF(Data!Q:Q,F3,Data!U:U),2) -> 25199.93 | I3: =SUMIF(Data!Q:Q,F3,Data!S:S) -> 20 | K3: =B3-G3 -> 0 | L3: =C3-H3 -> 0 | M3: =D3-I3 -> 0
A4: Fellowes PB500 Electric Punch Plastic Comb Binding Machine with Manual Bind | B4: 27453.38 | C4: 7753.04 | D4: 31 | F4: Fellowes PB500 Electric Punch Plastic Comb Binding Machine with Manual Bind | G4: =ROUND(SUMIF(Data!Q:Q,F4,Data!R:R),2) -> 27453.38 | H4: =ROUND(SUMIF(Data!Q:Q,F4,Data!U:U),2) -> 7753.04 | I4: =SUMIF(Data!Q:Q,F4,Data!S:S) -> 31 | K4: =B4-G4 -> 0 | L4: =C4-H4 -> 0 | M4: =D4-I4 -> 0
A5: Cisco TelePresence System EX90 Videoconferencing Unit | B5: 22638.48 | C5: -1811.08 | D5: 6 | F5: Cisco TelePresence System EX90 Videoconferencing Unit | G5: =ROUND(SUMIF(Data!Q:Q,F5,Data!R:R),2) -> 22638.48 | H5: =ROUND(SUMIF(Data!Q:Q,F5,Data!U:U),2) -> -1811.08 | I5: =SUMIF(Data!Q:Q,F5,Data!S:S) -> 6 | K5: =B5-G5 -> 0 | L5: =C5-H5 -> 0 | M5: =D5-I5 -> 0
A6: HON 5400 Series Task Chairs for Big and Tall | B6: 21870.58 | C6: 0 | D6: 39 | F6: HON 5400 Series Task Chairs for Big and Tall | G6: =ROUND(SUMIF(Data!Q:Q,F6,Data!R:R),2) -> 21870.58 | H6: =ROUND(SUMIF(Data!Q:Q,F6,Data!U:U),2) -> 0 | I6: =SUMIF(Data!Q:Q,F6,Data!S:S) -> 39 | K6: =B6-G6 -> 0 | L6: =C6-H6 -> 0 | M6: =D6-I6 -> 0
A7: GBC DocuBind TL300 Electric Binding System | B7: 19823.48 | C7: 2233.51 | D7: 37 | F7: GBC DocuBind TL300 Electric Binding System | G7: =ROUND(SUMIF(Data!Q:Q,F7,Data!R:R),2) -> 19823.48 | H7: =ROUND(SUMIF(Data!Q:Q,F7,Data!U:U),2) -> 2233.51 | I7: =SUMIF(Data!Q:Q,F7,Data!S:S) -> 37 | K7: =B7-G7 -> 0 | L7: =C7-H7 -> 0 | M7: =D7-I7 -> 0
A8: GBC Ibimaster 500 Manual ProClick Binding System | B8: 19024.5 | C8: 760.98 | D8: 48 | F8: GBC Ibimaster 500 Manual ProClick Binding System | G8: =ROUND(SUMIF(Data!Q:Q,F8,Data!R:R),2) -> 19024.5 | H8: =ROUND(SUMIF(Data!Q:Q,F8,Data!U:U),2) -> 760.98 | I8: =SUMIF(Data!Q:Q,F8,Data!S:S) -> 48 | K8: =B8-G8 -> 0 | L8: =C8-H8 -> 0 | M8: =D8-I8 -> 0
A9: Hewlett Packard LaserJet 3310 Copier | B9: 18839.69 | C9: 6983.88 | D9: 38 | F9: Hewlett Packard LaserJet 3310 Copier | G9: =ROUND(SUMIF(Data!Q:Q,F9,Data!R:R),2) -> 18839.69 | H9: =ROUND(SUMIF(Data!Q:Q,F9,Data!U:U),2) -> 6983.88 | I9: =SUMIF(Data!Q:Q,F9,Data!S:S) -> 38 | K9: =B9-G9 -> 0 | L9: =C9-H9 -> 0 | M9: =D9-I9 -> 0
A10: HP Designjet T520 Inkjet Large Format Printer - 24" Color | B10: 18374.9 | C10: 4094.98 | D10: 12 | F10: HP Designjet T520 Inkjet Large Format Printer - 24" Color | G10: =ROUND(SUMIF(Data!Q:Q,F10,Data!R:R),2) -> 18374.9 | H10: =ROUND(SUMIF(Data!Q:Q,F10,Data!U:U),2) -> 4094.98 | I10: =SUMIF(Data!Q:Q,F10,Data!S:S) -> 12 | K10: =B10-G10 -> 0 | L10: =C10-H10 -> 0 | M10: =D10-I10 -> 0
A11: GBC DocuBind P400 Electric Binding System | B11: 17965.07 | C11: -1878.17 | D11: 27 | F11: GBC DocuBind P400 Electric Binding System | G11: =ROUND(SUMIF(Data!Q:Q,F11,Data!R:R),2) -> 17965.07 | H11: =ROUND(SUMIF(Data!Q:Q,F11,Data!U:U),2) -> -1878.17 | I11: =SUMIF(Data!Q:Q,F11,Data!S:S) -> 27 | K11: =B11-G11 -> 0 | L11: =C11-H11 -> 0 | M11: =D11-I11 -> 0
A12: High Speed Automatic Electric Letter Opener | B12: 17030.31 | C12: -262 | D12: 11 | F12: High Speed Automatic Electric Letter Opener | G12: =ROUND(SUMIF(Data!Q:Q,F12,Data!R:R),2) -> 17030.31 | H12: =ROUND(SUMIF(Data!Q:Q,F12,Data!U:U),2) -> -262 | I12: =SUMIF(Data!Q:Q,F12,Data!S:S) -> 11 | K12: =B12-G12 -> 0 | L12: =C12-H12 -> 0 | M12: =D12-I12 -> 0
F13: Lexmark MX611dhe Monochrome Laser Printer | G13: =ROUND(SUMIF(Data!Q:Q,F13,Data!R:R),2) -> 16829.9 | H13: =ROUND(SUMIF(Data!Q:Q,F13,Data!U:U),2) -> -4589.97 | I13: =SUMIF(Data!Q:Q,F13,Data!S:S) -> 18
F14: Martin Yale Chadless Opener Electric Letter Opener | G14: =ROUND(SUMIF(Data!Q:Q,F14,Data!R:R),2) -> 16656.2 | H14: =ROUND(SUMIF(Data!Q:Q,F14,Data!U:U),2) -> -1299.18 | I14: =SUMIF(Data!Q:Q,F14,Data!S:S) -> 22
F15: Ibico EPK-21 Electric Binding System | G15: =ROUND(SUMIF(Data!Q:Q,F15,Data!R:R),2) -> 15875.92 | H15: =ROUND(SUMIF(Data!Q:Q,F15,Data!U:U),2) -> 3345.28 | I15: =SUMIF(Data!Q:Q,F15,Data!S:S) -> 13
F16: Riverside Palais Royal Lawyers Bookcase, Royale Cherry Finish | G16: =ROUND(SUMIF(Data!Q:Q,F16,Data!R:R),2) -> 15610.97 | H16: =ROUND(SUMIF(Data!Q:Q,F16,Data!U:U),2) -> -669.54 | I16: =SUMIF(Data!Q:Q,F16,Data!S:S) -> 24
F17: 3D Systems Cube Printer, 2nd Generation, Magenta | G17: =ROUND(SUMIF(Data!Q:Q,F17,Data!R:R),2) -> 14299.89 | H17: =ROUND(SUMIF(Data!Q:Q,F17,Data!U:U),2) -> 3717.97 | I17: =SUMIF(Data!Q:Q,F17,Data!S:S) -> 11
F18: Samsung Galaxy Mega 6.3 | G18: =ROUND(SUMIF(Data!Q:Q,F18,Data!R:R),2) -> 13943.67 | H18: =ROUND(SUMIF(Data!Q:Q,F18,Data!U:U),2) -> 1822.76 | I18: =SUMIF(Data!Q:Q,F18,Data!S:S) -> 39
F19: Apple iPhone 5 | G19: =ROUND(SUMIF(Data!Q:Q,F19,Data!R:R),2) -> 12996.6 | H19: =ROUND(SUMIF(Data!Q:Q,F19,Data!U:U),2) -> 1611.58 | I19: =SUMIF(Data!Q:Q,F19,Data!S:S) -> 24
F20: Bretford Rectangular Conference Table Tops | G20: =ROUND(SUMIF(Data!Q:Q,F20,Data!R:R),2) -> 12995.29 | H20: =ROUND(SUMIF(Data!Q:Q,F20,Data!U:U),2) -> -327.23 | I20: =SUMIF(Data!Q:Q,F20,Data!S:S) -> 46
F21: Global Troy Executive Leather Low-Back Tilter | G21: =ROUND(SUMIF(Data!Q:Q,F21,Data!R:R),2) -> 12975.38 | H21: =ROUND(SUMIF(Data!Q:Q,F21,Data!U:U),2) -> 951.86 | I21: =SUMIF(Data!Q:Q,F21,Data!S:S) -> 32
F22: Canon PC1060 Personal Laser Copier | G22: =ROUND(SUMIF(Data!Q:Q,F22,Data!R:R),2) -> 11619.83 | H22: =ROUND(SUMIF(Data!Q:Q,F22,Data!U:U),2) -> 4570.93 | I22: =SUMIF(Data!Q:Q,F22,Data!S:S) -> 19
F23: SAFCO Arco Folding Chair | G23: =ROUND(SUMIF(Data!Q:Q,F23,Data!R:R),2) -> 11572.78 | H23: =ROUND(SUMIF(Data!Q:Q,F23,Data!U:U),2) -> 1179.37 | I23: =SUMIF(Data!Q:Q,F23,Data!S:S) -> 53
F24: Honeywell Enviracaire Portable HEPA Air Cleaner for 17' x 22' Room | G24: =ROUND(SUMIF(Data!Q:Q,F24,Data!R:R),2) -> 11304.44 | H24: =ROUND(SUMIF(Data!Q:Q,F24,Data!U:U),2) -> 3247.02 | I24: =SUMIF(Data!Q:Q,F24,Data!S:S) -> 40
... F1852: Eureka Disposable Bags for Sanitaire Vibra Groomer I Upright Vac | G1852: =ROUND(SUMIF(Data!Q:Q,F1852,Data!R:R),2) -> 1.62 | H1852: =ROUND(SUMIF(Data!Q:Q,F1852,Data!U:U),2) -> -4.47 | I1852: =SUMIF(Data!Q:Q,F1852,Data!S:S) -> 2

Sheet 5-1
A1: Q3
A2: Segment | B2: Total_Sales | C2: Total_Quantity
A3: Consumer | B3: 1161401.3 | C3: 19521
A4: Corporate | B4: 706146.37 | C4: 11608
A5: Home Office | B5: 429653.15 | C5: 6744

Sheet 5-2
A1: SQL | F1: Excel
A2: Customer_Name | B2: Total_Sales | C2: Order_Times | D2: Average_Spending | F2: Customer_Name | G2: Total_Sales | H2: Order_Times | I2: Average_Spending | K2: check
A3: Sean Miller | B3: 25043.05 | C3: 5 | D3: 5008.61 | F3: =A3 -> Sean Miller | G3: =ROUND(SUMIF(Data!G:G,F3,Data!R:R),2) -> 25043.05 | H3: {=COUNTA(_xlfn.UNIQUE(_xlfn._xlws.FILTER(Data!B:B,Data!G:G=F3)))} -> 5 | I3: =ROUND(G3/H3,2) -> 5008.61 | K3: =G3-B3 -> 0 | L3: =H3-C3 -> 0 | M3: =I3-D3 -> 0
A4: Tamara Chand | B4: 19052.22 | C4: 5 | D4: 3810.44 | F4: =A4 -> Tamara Chand | G4: =ROUND(SUMIF(Data!G:G,F4,Data!R:R),2) -> 19052.22 | H4: {=COUNTA(_xlfn.UNIQUE(_xlfn._xlws.FILTER(Data!B:B,Data!G:G=F4)))} -> 5 | I4: =ROUND(G4/H4,2) -> 3810.44 | K4: =G4-B4 -> 0 | L4: =H4-C4 -> 0 | M4: =I4-D4 -> 0
A5: Tom Ashbrook | B5: 14595.62 | C5: 4 | D5: 3648.9 | F5: =A5 -> Tom Ashbrook | G5: =ROUND(SUMIF(Data!G:G,F5,Data!R:R),2) -> 14595.62 | H5: {=COUNTA(_xlfn.UNIQUE(_xlfn._xlws.FILTER(Data!B:B,Data!G:G=F5)))} -> 4 | I5: =ROUND(G5/H5,2) -> 3648.91 | K5: =G5-B5 -> 0 | L5: =H5-C5 -> 0 | M5: =I5-D5 -> 0.01
A6: Grant Thornton | B6: 9351.21 | C6: 3 | D6: 3117.07 | F6: =A6 -> Grant Thornton | G6: =ROUND(SUMIF(Data!G:G,F6,Data!R:R),2) -> 9351.21 | H6: {=COUNTA(_xlfn.UNIQUE(_xlfn._xlws.FILTER(Data!B:B,Data!G:G=F6)))} -> 3 | I6: =ROUND(G6/H6,2) -> 3117.07 | K6: =G6-B6 -> 0 | L6: =H6-C6 -> 0 | M6: =I6-D6 -> 0
A7: Becky Martin | B7: 11789.63 | C7: 4 | D7: 2947.41 | F7: =A7 -> Becky Martin | G7: =ROUND(SUMIF(Data!G:G,F7,Data!R:R),2) -> 11789.63 | H7: {=COUNTA(_xlfn.UNIQUE(_xlfn._xlws.FILTER(Data!B:B,Data!G:G=F7)))} -> 4 | I7: =ROUND(G7/H7,2) -> 2947.41 | K7: =G7-B7 -> 0 | L7: =H7-C7 -> 0 | M7: =I7-D7 -> 0
A8: Mitch Willingham | B8: 5253.88 | C8: 2 | D8: 2626.94 | F8: =A8 -> Mitch Willingham | G8: =ROUND(SUMIF(Data!G:G,F8,Data!R:R),2) -> 5253.88 | H8: {=COUNTA(_xlfn.UNIQUE(_xlfn._xlws.FILTER(Data!B:B,Data!G:G=F8)))} -> 2 | I8: =ROUND(G8/H8,2) -> 2626.94 | K8: =G8-B8 -> 0 | L8: =H8-C8 -> 0 | M8: =I8-D8 -> 0
A9: Raymond Buch | B9: 15117.34 | C9: 6 | D9: 2519.56 | F9: =A9 -> Raymond Buch | G9: =ROUND(SUMIF(Data!G:G,F9,Data!R:R),2) -> 15117.34 | H9: {=COUNTA(_xlfn.UNIQUE(_xlfn._xlws.FILTER(Data!B:B,Data!G:G=F9)))} -> 6 | I9: =ROUND(G9/H9,2) -> 2519.56 | K9: =G9-B9 -> 0 | L9: =H9-C9 -> 0 | M9: =I9-D9 -> 0
A10: Christopher Conant | B10: 12129.07 | C10: 5 | D10: 2425.81 | F10: =A10 -> Christopher Conant | G10: =ROUND(SUMIF(Data!G:G,F10,Data!R:R),2) -> 12129.07 | H10: {=COUNTA(_xlfn.UNIQUE(_xlfn._xlws.FILTER(Data!B:B,Data!G:G=F10)))} -> 5 | I10: =ROUND(G10/H10,2) -> 2425.81 | K10: =G10-B10 -> 0 | L10: =H10-C10 -> 0 | M10: =I10-D10 -> 0
A11: Peter Fuller | B11: 9062.86 | C11: 4 | D11: 2265.72 | F11: =A11 -> Peter Fuller | G11: =ROUND(SUMIF(Data!G:G,F11,Data!R:R),2) -> 9062.86 | H11: {=COUNTA(_xlfn.UNIQUE(_xlfn._xlws.FILTER(Data!B:B,Data!G:G=F11)))} -> 4 | I11: =ROUND(G11/H11,2) -> 2265.72 | K11: =G11-B11 -> 0 | L11: =H11-C11 -> 0 | M11: =I11-D11 -> 0
A12: Christopher Martinez | B12: 8954.02 | C12: 4 | D12: 2238.5 | F12: =A12 -> Christopher Martinez | G12: =ROUND(SUMIF(Data!G:G,F12,Data!R:R),2) -> 8954.02 | H12: {=COUNTA(_xlfn.UNIQUE(_xlfn._xlws.FILTER(Data!B:B,Data!G:G=F12)))} -> 4 | I12: =ROUND(G12/H12,2) -> 2238.51 | K12: =G12-B12 -> 0 | L12: =H12-C12 -> 0 | M12: =I12-D12 -> 0.01
A13: Hunter Lopez | B13: 12873.3 | C13: 6 | D13: 2145.55 | F13: =A13 -> Hunter Lopez | G13: =ROUND(SUMIF(Data!G:G,F13,Data!R:R),2) -> 12873.3 | H13: {=COUNTA(_xlfn.UNIQUE(_xlfn._xlws.FILTER(Data!B:B,Data!G:G=F13)))} -> 6 | I13: =ROUND(G13/H13,2) -> 2145.55 | K13: =G13-B13 -> 0 | L13: =H13-C13 -> 0 | M13: =I13-D13 -> 0
A14: Bill Shonely | B14: 10501.65 | C14: 5 | D14: 2100.33 | F14: =A14 -> Bill Shonely | G14: =ROUND(SUMIF(Data!G:G,F14,Data!R:R),2) -> 10501.65 | H14: {=COUNTA(_xlfn.UNIQUE(_xlfn._xlws.FILTER(Data!B:B,Data!G:G=F14)))} -> 5 | I14: =ROUND(G14/H14,2) -> 2100.33 | K14: =G14-B14 -> 0 | L14: =H14-C14 -> 0 | M14: =I14-D14 -> 0
... A52: Rick Wilson | B52: 7397.4 | C52: 7 | D52: 1056.77 | F52: =A52 -> Rick Wilson | G52: =ROUND(SUMIF(Data!G:G,F52,Data!R:R),2) -> 7397.4 | H52: {=COUNTA(_xlfn.UNIQUE(_xlfn._xlws.FILTER(Data!B:B,Data!G:G=F52)))} -> 7 | I52: =ROUND(G52/H52,2) -> 1056.77 | K52: =G52-B52 -> 0 | L52: =H52-C52 -> 0 | M52: =I52-D52 -> 0
